Workbook

Sheet Petunjuk
A1: Templat SLR-RQ1 — Disertasi 3.0
A2: RQ1: Bagaimana Computational Thinking dikonseptualisasikan, dikembangkan, dan diukur dalam pembelajaran fisika dan Earth Science (2016–2026)?
A4: Cara pakai
A5: 1. Log_Pencarian — catat setiap pencarian: tanggal, basis data, string persis, jumlah hasil.
A6: 2. Screening — tempel hasil ekspor Scopus/WoS/ERIC (Penulis, Tahun, Judul, Jurnal, DOI, Abstrak), lalu isi keputusan.
A7: 3. Ekstraksi_RQ1 — satu baris per artikel yang lolos full-text.
A8: 4. Rekap dan PRISMA — terisi otomatis dengan rumus; jangan diketik manual.
A10: Legenda
A11: Sel kuning = diisi peneliti. Kolom dengan dropdown mengambil kategori dari lembar Kodebook.
A12: Baris hijau berlabel CONTOH = contoh format pengisian; boleh dihapus. Baris CONTOH tidak ikut dihitung di Rekap/PRISMA.
A13: Kolom 'Halaman bukti' wajib diisi agar setiap kode dapat ditelusuri ke teks asli.
A15: Pembagian kerja
... A17: Claude: dedup, screening tahap pertama, ekstraksi dari PDF, rekap, grafik, draf narasi. Keputusan akhir tetap pada peneliti.

Sheet Log_Pencarian
A1: No | B1: Tanggal | C1: Basis data | D1: String pencarian (persis) | E1: Filter | F1: Jumlah hasil | G1: Keterangan
A2: CONTOH | B2: 2026-10-15 | C2: Scopus | D2: TITLE-ABS-KEY("computational thinking") AND TITLE-ABS-KEY(physics OR "earth science*" ...) | E2: 2016–2026; ar/cp/re; English | F2: 0 | G2: Angka contoh; ganti dengan hasil nyata

Sheet Screening
A1: Screening (PRISMA). Tempel hasil ekspor mulai baris 4; baris 3 = CONTOH.
A2: No | B2: Basis data | C2: Penulis | D2: Tahun | E2: Judul | F2: Jurnal/Prosiding | G2: DOI | H2: Abstrak | I2: Duplikat? | J2: Keputusan judul-abstrak | K2: Kode eksklusi (TA) | L2: Alasan singkat | M2: Keputusan full-text | N2: Kode eksklusi (FT) | O2: Diverifikasi peneliti?
A3: CONTOH | B3: Scopus | C3: Hutchins, N. M., et al. | D3: 2020 | E3: C2STEM: A system for synergistic learning of physics and computational thinking | F3: Journal of Science Education and Technology | G3: 10.1007/s10956-019-09804-9 | H3: (tempel abstrak) | I3: Tidak | J3: Include | L3: CT dan fisika eksplisit; SMA; pemodelan komputasional | M3: Include | O3: Ya

Sheet Ekstraksi_RQ1
A1: Identitas | G1: 1a Karakteristik | M1: 1b Konseptualisasi | P1: 1c Pengembangan | W1: 1d Pengukuran | AA1: 1e Hasil | AD1: Jejak
A2: ID | B2: Penulis | C2: Tahun | D2: Judul | E2: Jurnal | F2: Negara | G2: Jenjang | H2: Subjek calon guru? | I2: Desain penelitian | J2: Ukuran sampel (N) | K2: Domain | L2: Materi/topik | M2: Definisi CT yang dikutip | N2: Kerangka CT | O2: Komponen CT yang dipakai | P2: Model/pendekatan pembelajaran | Q2: Plugged/Unplugged | R2: Alat/software | S2: Ada Computational Modeling? | T2: Jenis masalah | U2: Ada argumentasi? | V2: Ada PBL/STEM? | W2: Jenis instrumen | X2: Nama instrumen | Y2: Komponen yang diukur | Z2: Validitas/reliabilitas dilaporkan? | AA2: Temuan utama | AB2: Keterbatasan | AC2: Rekomendasi penelitian lanjutan | AD2: Halaman bukti | AE2: Catatan | AF2: Pengkode
A3: CONTOH | B3: Hutchins, N. M., et al. | C3: 2020 | D3: C2STEM: A system for synergistic learning of physics and computational thinking | E3: J. Sci. Educ. Technol. | F3: AS | G3: SMA/MA/SMK | H3: Tidak | I3: Mixed methods | J3: (isi dari artikel) | K3: Fisika | L3: Kinematika/gerak benda | M3: (kutip definisi CT dari artikel) | N3: Weintrop dkk. (2016) | O3: (isi dari artikel) | P3: Learning-by-modeling, design-based | Q3: Plugged | R3: C2STEM (visual + DSML) | S3: Ya | T3: Soal terstruktur | U3: Tidak | V3: Tidak | W3: Kombinasi | X3: Preparation for future learning assessment | Y3: (isi dari artikel) | Z3: Tidak jelas | AA3: (isi dari artikel) | AB3: (isi dari artikel) | AC3: (isi dari artikel) | AD3: hlm. ... | AE3: Baris contoh: kategori yang tidak dicek dari teks lengkap ditandai (isi dari artikel) | AF3: Claude

Sheet Rekap
A1: Rekap otomatis dari Ekstraksi_RQ1 (baris CONTOH tidak dihitung)
A3: Total artikel dianalisis | B3: =COUNTIFS(Ekstraksi_RQ1!$A$3:$A$300,"<>CONTOH",Ekstraksi_RQ1!$D$3:$D$300,"<>") -> 0
A5: 1a Jenjang/subjek | B5: Jumlah | C5: %
A6: SMP | B6: =COUNTIFS(Ekstraksi_RQ1!$G$3:$G$300,A6,Ekstraksi_RQ1!$A$3:$A$300,"<>CONTOH") -> 0 | C6: =IF($B$3=0,0,B6/$B$3) -> 0
A7: SMA/MA/SMK | B7: =COUNTIFS(Ekstraksi_RQ1!$G$3:$G$300,A7,Ekstraksi_RQ1!$A$3:$A$300,"<>CONTOH") -> 0 | C7: =IF($B$3=0,0,B7/$B$3) -> 0
A8: Sarjana (non-guru) | B8: =COUNTIFS(Ekstraksi_RQ1!$G$3:$G$300,A8,Ekstraksi_RQ1!$A$3:$A$300,"<>CONTOH") -> 0 | C8: =IF($B$3=0,0,B8/$B$3) -> 0
A9: Calon guru (pre-service) | B9: =COUNTIFS(Ekstraksi_RQ1!$G$3:$G$300,A9,Ekstraksi_RQ1!$A$3:$A$300,"<>CONTOH") -> 0 | C9: =IF($B$3=0,0,B9/$B$3) -> 0
A10: Guru (in-service) | B10: =COUNTIFS(Ekstraksi_RQ1!$G$3:$G$300,A10,Ekstraksi_RQ1!$A$3:$A$300,"<>CONTOH") -> 0 | C10: =IF($B$3=0,0,B10/$B$3) -> 0
A11: Campuran | B11: =COUNTIFS(Ekstraksi_RQ1!$G$3:$G$300,A11,Ekstraksi_RQ1!$A$3:$A$300,"<>CONTOH") -> 0 | C11: =IF($B$3=0,0,B11/$B$3) -> 0
A13: 1a Domain | B13: Jumlah | C13: %
A14: Fisika | B14: =COUNTIFS(Ekstraksi_RQ1!$K$3:$K$300,A14,Ekstraksi_RQ1!$A$3:$A$300,"<>CONTOH") -> 0 | C14: =IF($B$3=0,0,B14/$B$3) -> 0
A15: Earth Science | B15: =COUNTIFS(Ekstraksi_RQ1!$K$3:$K$300,A15,Ekstraksi_RQ1!$A$3:$A$300,"<>CONTOH") -> 0 | C15: =IF($B$3=0,0,B15/$B$3) -> 0
A16: Keduanya | B16: =COUNTIFS(Ekstraksi_RQ1!$K$3:$K$300,A16,Ekstraksi_RQ1!$A$3:$A$300,"<>CONTOH") -> 0 | C16: =IF($B$3=0,0,B16/$B$3) -> 0
A18: 1a Desain penelitian | B18: Jumlah | C18: %
A19: Eksperimen/kuasi-eksperimen | B19: =COUNTIFS(Ekstraksi_RQ1!$I$3:$I$300,A19,Ekstraksi_RQ1!$A$3:$A$300,"<>CONTOH") -> 0 | C19: =IF($B$3=0,0,B19/$B$3) -> 0
A20: Pra-eksperimen | B20: =COUNTIFS(Ekstraksi_RQ1!$I$3:$I$300,A20,Ekstraksi_RQ1!$A$3:$A$300,"<>CONTOH") -> 0 | C20: =IF($B$3=0,0,B20/$B$3) -> 0
A21: Kualitatif/studi kasus | B21: =COUNTIFS(Ekstraksi_RQ1!$I$3:$I$300,A21,Ekstraksi_RQ1!$A$3:$A$300,"<>CONTOH") -> 0 | C21: =IF($B$3=0,0,B21/$B$3) -> 0
A22: Mixed methods | B22: =COUNTIFS(Ekstraksi_RQ1!$I$3:$I$300,A22,Ekstraksi_RQ1!$A$3:$A$300,"<>CONTOH") -> 0 | C22: =IF($B$3=0,0,B22/$B$3) -> 0
A23: D&D/EDR/DBR | B23: =COUNTIFS(Ekstraksi_RQ1!$I$3:$I$300,A23,Ekstraksi_RQ1!$A$3:$A$300,"<>CONTOH") -> 0 | C23: =IF($B$3=0,0,B23/$B$3) -> 0
A24: Survei | B24: =COUNTIFS(Ekstraksi_RQ1!$I$3:$I$300,A24,Ekstraksi_RQ1!$A$3:$A$300,"<>CONTOH") -> 0 | C24: =IF($B$3=0,0,B24/$B$3) -> 0
A25: Lainnya | B25: =COUNTIFS(Ekstraksi_RQ1!$I$3:$I$300,A25,Ekstraksi_RQ1!$A$3:$A$300,"<>CONTOH") -> 0 | C25: =IF($B$3=0,0,B25/$B$3) -> 0
A27: 1b Kerangka CT | B27: Jumlah | C27: %
A28: Wing (2006) | B28: =COUNTIFS(Ekstraksi_RQ1!$N$3:$N$300,A28,Ekstraksi_RQ1!$A$3:$A$300,"<>CONTOH") -> 0 | C28: =IF($B$3=0,0,B28/$B$3) -> 0
A29: Brennan & Resnick (2012) | B29: =COUNTIFS(Ekstraksi_RQ1!$N$3:$N$300,A29,Ekstraksi_RQ1!$A$3:$A$300,"<>CONTOH") -> 0 | C29: =IF($B$3=0,0,B29/$B$3) -> 0
A30: Weintrop dkk. (2016) | B30: =COUNTIFS(Ekstraksi_RQ1!$N$3:$N$300,A30,Ekstraksi_RQ1!$A$3:$A$300,"<>CONTOH") -> 0 | C30: =IF($B$3=0,0,B30/$B$3) -> 0
A31: Shute dkk. (2017) | B31: =COUNTIFS(Ekstraksi_RQ1!$N$3:$N$300,A31,Ekstraksi_RQ1!$A$3:$A$300,"<>CONTOH") -> 0 | C31: =IF($B$3=0,0,B31/$B$3) -> 0
A32: Grover & Pea (2013) | B32: =COUNTIFS(Ekstraksi_RQ1!$N$3:$N$300,A32,Ekstraksi_RQ1!$A$3:$A$300,"<>CONTOH") -> 0 | C32: =IF($B$3=0,0,B32/$B$3) -> 0
A33: CSTA/ISTE | B33: =COUNTIFS(Ekstraksi_RQ1!$N$3:$N$300,A33,Ekstraksi_RQ1!$A$3:$A$300,"<>CONTOH") -> 0 | C33: =IF($B$3=0,0,B33/$B$3) -> 0
A34: BBC Bitesize/Google (4 pilar) | B34: =COUNTIFS(Ekstraksi_RQ1!$N$3:$N$300,A34,Ekstraksi_RQ1!$A$3:$A$300,"<>CONTOH") -> 0 | C34: =IF($B$3=0,0,B34/$B$3) -> 0
A35: Kerangka sendiri | B35: =COUNTIFS(Ekstraksi_RQ1!$N$3:$N$300,A35,Ekstraksi_RQ1!$A$3:$A$300,"<>CONTOH") -> 0 | C35: =IF($B$3=0,0,B35/$B$3) -> 0
A36: Tidak disebut | B36: =COUNTIFS(Ekstraksi_RQ1!$N$3:$N$300,A36,Ekstraksi_RQ1!$A$3:$A$300,"<>CONTOH") -> 0 | C36: =IF($B$3=0,0,B36/$B$3) -> 0
A38: 1c Plugged/unplugged | B38: Jumlah | C38: %
A39: Plugged | B39: =COUNTIFS(Ekstraksi_RQ1!$Q$3:$Q$300,A39,Ekstraksi_RQ1!$A$3:$A$300,"<>CONTOH") -> 0 | C39: =IF($B$3=0,0,B39/$B$3) -> 0
A40: Unplugged | B40: =COUNTIFS(Ekstraksi_RQ1!$Q$3:$Q$300,A40,Ekstraksi_RQ1!$A$3:$A$300,"<>CONTOH") -> 0 | C40: =IF($B$3=0,0,B40/$B$3) -> 0
A41: Keduanya | B41: =COUNTIFS(Ekstraksi_RQ1!$Q$3:$Q$300,A41,Ekstraksi_RQ1!$A$3:$A$300,"<>CONTOH") -> 0 | C41: =IF($B$3=0,0,B41/$B$3) -> 0
A43: 1c Ada Computational Modeling? | B43: Jumlah | C43: %
A44: Ya | B44: =COUNTIFS(Ekstraksi_RQ1!$S$3:$S$300,A44,Ekstraksi_RQ1!$A$3:$A$300,"<>CONTOH") -> 0 | C44: =IF($B$3=0,0,B44/$B$3) -> 0
A45: Tidak | B45: =COUNTIFS(Ekstraksi_RQ1!$S$3:$S$300,A45,Ekstraksi_RQ1!$A$3:$A$300,"<>CONTOH") -> 0 | C45: =IF($B$3=0,0,B45/$B$3) -> 0
A46: Tidak jelas | B46: =COUNTIFS(Ekstraksi_RQ1!$S$3:$S$300,A46,Ekstraksi_RQ1!$A$3:$A$300,"<>CONTOH") -> 0 | C46: =IF($B$3=0,0,B46/$B$3) -> 0
A48: 1c Jenis masalah | B48: Jumlah | C48: %
...

Sheet PRISMA
A1: Angka diagram PRISMA 2020 (otomatis)
A2: IDENTIFIKASI
A3: Rekaman teridentifikasi dari basis data (jumlah Log_Pencarian) | B3: =SUMIFS(Log_Pencarian!$F$2:$F$20,Log_Pencarian!$A$2:$A$20,"<>CONTOH") -> 0
A4: Rekaman di lembar Screening | B4: =COUNTIFS(Screening!$A$3:$A$500,"<>CONTOH",Screening!$E$3:$E$500,"<>") -> 0
A5: Duplikat dihapus | B5: =COUNTIFS(Screening!$A$3:$A$500,"<>CONTOH",Screening!$I$3:$I$500,"Ya") -> 0
A6: SCREENING
A7: Rekaman di-screening (judul-abstrak) | B7: =B4-B5 -> 0
A8: Dikeluarkan pada judul-abstrak | B8: =COUNTIFS(Screening!$A$3:$A$500,"<>CONTOH",Screening!$J$3:$J$500,"Exclude",Screening!$I$3:$I$500,"<>Ya") -> 0
A9: Dinilai teks lengkap (Include + Ragu) | B9: =COUNTIFS(Screening!$A$3:$A$500,"<>CONTOH",Screening!$J$3:$J$500,"Include",Screening!$I$3:$I$500,"<>Ya")+COUNTIFS(Screening!$A$3:$A$500,"<>CONTOH",Screening!$J$3:$J$500,"Ragu",Screening!$I$3:$I$500,"<>Ya") -> 0
A10: Dikeluarkan pada teks lengkap | B10: =COUNTIFS(Screening!$A$3:$A$500,"<>CONTOH",Screening!$M$3:$M$500,"Exclude",Screening!$I$3:$I$500,"<>Ya") -> 0
A11: INKLUSI
A12: Studi masuk sintesis (dari screening) | B12: =COUNTIFS(Screening!$A$3:$A$500,"<>CONTOH",Screening!$M$3:$M$500,"Include",Screening!$I$3:$I$500,"<>Ya") -> 0
A13: Tambahan dari snowballing (isi manual) | B13: 0 | C13: Input manual: jumlah artikel tambahan dari backward/forward snowballing
A14: Total studi masuk sintesis | B14: =B12+B13 -> 0
A15: Cek: rekaman di Screening vs Log (selisih) | B15: =B3-B4 -> 0 | C15: Selisih ≠ 0 wajar bila sebagian hasil Log belum ditempel ke Screening

Sheet Kodebook
A1: Kodebook: daftar kategori untuk dropdown. Tambah kategori di bawah kolom yang sesuai bila perlu (range dropdown s.d. baris 30).
A2: Keputusan | B2: Kode_Eksklusi | C2: YaTidak | D2: Jenjang | E2: Domain | F2: Desain | G2: Kerangka_CT | H2: Plugged | I2: Masalah | J2: Instrumen
A3: Include | B3: E1 CT sekilas | C3: Ya | D3: SMP | E3: Fisika | F3: Eksperimen/kuasi-eksperimen | G3: Wing (2006) | H3: Plugged | I3: Autentik/ill-structured | J3: Tes CT (pilihan ganda/esai)
A4: Exclude | B4: E2 Bukan fisika/Earth Sci | C4: Tidak | D4: SMA/MA/SMK | E4: Earth Science | F4: Pra-eksperimen | G4: Brennan & Resnick (2012) | H4: Unplugged | I4: Soal terstruktur | J4: Skala/kuesioner disposisi
A5: Ragu | B5: E3 Bukan pendidikan | C5: Tidak jelas | D5: Sarjana (non-guru) | E5: Keduanya | F5: Kualitatif/studi kasus | G5: Weintrop dkk. (2016) | H5: Keduanya | I5: Campuran | J5: Rubrik kinerja/proyek
B6: E4 Review/opini | D6: Calon guru (pre-service) | F6: Mixed methods | G6: Shute dkk. (2017) | I6: Tidak jelas | J6: Analisis artefak/kode
B7: E5 Full-text tak ada | D7: Guru (in-service) | F7: D&D/EDR/DBR | G7: Grover & Pea (2013) | J7: Observasi/wawancara
B8: E6 Duplikat | D8: Campuran | F8: Survei | G8: CSTA/ISTE | J8: Kombinasi
F9: Lainnya | G9: BBC Bitesize/Google (4 pilar) | J9: Tidak diukur
G10: Kerangka sendiri
G11: Tidak disebut
